 ****** Running generation 0 ******
Average fitness:
Failed mean
Best fitness:
Traceback (most recent call last):
  File "C:\Projects\Code\Neurals\testing.py", line 105, in eval_genomes
    meanfit = numpy.array(stats.get_fitness_mean())[-1]
IndexError: index -1 is out of bounds for axis 0 with size 0
During handling of the above exception, another exception occurred:
Traceback (most recent call last):
  File "C:\Projects\Code\Neurals\testing.py", line 190, in <module>
    run(config_path)
  File "C:\Projects\Code\Neurals\testing.py", line 173, in run
    winner = pop.run(eval_genomes, 50)
  File "C:\Users\Maxim N\AppData\Local\Packages\PythonSoftwareFoundation.Python.3.9_qbz5n2kfra8p0\LocalCache\local-packages\Python39\site-packages\neat\population.py", line 89, in run
    fitness_function(list(iteritems(self.population)), self.config)
  File "C:\Projects\Code\Neurals\testing.py", line 112, in eval_genomes
    bestfit = stats.best_genome().fitness
  File "C:\Users\Maxim N\AppData\Local\Packages\PythonSoftwareFoundation.Python.3.9_qbz5n2kfra8p0\LocalCache\local-packages\Python39\site-packages\neat\statistics.py", line 94, in best_genome
    return self.best_genomes(1)[0]
IndexError: list index out of range